[2023-02-20 13:38:58,054] {taskinstance.py:1159} INFO - Dependencies all met for <TaskInstance: autoetl-coordinates.get_mapping manual__2023-02-20T12:55:37.672912+00:00 [queued]>
[2023-02-20 13:38:58,067] {taskinstance.py:1159} INFO - Dependencies all met for <TaskInstance: autoetl-coordinates.get_mapping manual__2023-02-20T12:55:37.672912+00:00 [queued]>
[2023-02-20 13:38:58,069] {taskinstance.py:1356} INFO - 
--------------------------------------------------------------------------------
[2023-02-20 13:38:58,070] {taskinstance.py:1357} INFO - Starting attempt 1 of 1
[2023-02-20 13:38:58,071] {taskinstance.py:1358} INFO - 
--------------------------------------------------------------------------------
[2023-02-20 13:38:58,087] {taskinstance.py:1377} INFO - Executing <Task(PythonOperator): get_mapping> on 2023-02-20 12:55:37.672912+00:00
[2023-02-20 13:38:58,101] {standard_task_runner.py:52} INFO - Started process 1262 to run task
[2023-02-20 13:38:58,107] {standard_task_runner.py:79} INFO - Running: ['***', 'tasks', 'run', 'autoetl-coordinates', 'get_mapping', 'manual__2023-02-20T12:55:37.672912+00:00', '--job-id', '9', '--raw', '--subdir', 'DAGS_FOLDER/autoetl-coordinates.py', '--cfg-path', '/tmp/tmpbakfittm', '--error-file', '/tmp/tmprtjdyu0z']
[2023-02-20 13:38:58,108] {standard_task_runner.py:80} INFO - Job 9: Subtask get_mapping
[2023-02-20 13:38:58,176] {task_command.py:369} INFO - Running <TaskInstance: autoetl-coordinates.get_mapping manual__2023-02-20T12:55:37.672912+00:00 [running]> on host 08ba3386fdbc
[2023-02-20 13:38:58,258] {taskinstance.py:1571} INFO - Exporting the following env vars:
AIRFLOW_CTX_DAG_OWNER=***
AIRFLOW_CTX_DAG_ID=autoetl-coordinates
AIRFLOW_CTX_TASK_ID=get_mapping
AIRFLOW_CTX_EXECUTION_DATE=2023-02-20T12:55:37.672912+00:00
AIRFLOW_CTX_TRY_NUMBER=1
AIRFLOW_CTX_DAG_RUN_ID=manual__2023-02-20T12:55:37.672912+00:00
[2023-02-20 13:38:58,260] {logging_mixin.py:115} INFO - Load Data
[2023-02-20 13:39:00,036] {logging_mixin.py:115} WARNING - /home/***/.local/lib/python3.7/site-packages/***/operators/python.py:189 DtypeWarning: Columns (13,14,16,22) have mixed types.Specify dtype option on import or set low_memory=False.
[2023-02-20 13:39:47,914] {logging_mixin.py:115} INFO - Load mapping config
[2023-02-20 13:39:47,955] {logging_mixin.py:115} INFO - User Guide: https://docs.kepler.gl/docs/keplergl-jupyter
[2023-02-20 13:40:07,248] {logging_mixin.py:115} INFO - Map saved to ./data/outputs/newgeo_map.html!
[2023-02-20 13:40:07,727] {python.py:173} INFO - Done. Returned value was: None
[2023-02-20 13:40:07,751] {taskinstance.py:1400} INFO - Marking task as SUCCESS. dag_id=autoetl-coordinates, task_id=get_mapping, execution_date=20230220T125537, start_date=20230220T133858, end_date=20230220T134007
[2023-02-20 13:40:08,173] {local_task_job.py:156} INFO - Task exited with return code 0
[2023-02-20 13:40:08,227] {local_task_job.py:273} INFO - 0 downstream tasks scheduled from follow-on schedule check
