[2023-02-19 14:31:49,564] {taskinstance.py:1159} INFO - Dependencies all met for <TaskInstance: autoetl-coordinates.get_input_data manual__2023-02-19T14:31:47.482838+00:00 [queued]>
[2023-02-19 14:31:49,578] {taskinstance.py:1159} INFO - Dependencies all met for <TaskInstance: autoetl-coordinates.get_input_data manual__2023-02-19T14:31:47.482838+00:00 [queued]>
[2023-02-19 14:31:49,579] {taskinstance.py:1356} INFO - 
--------------------------------------------------------------------------------
[2023-02-19 14:31:49,580] {taskinstance.py:1357} INFO - Starting attempt 1 of 1
[2023-02-19 14:31:49,582] {taskinstance.py:1358} INFO - 
--------------------------------------------------------------------------------
[2023-02-19 14:31:49,599] {taskinstance.py:1377} INFO - Executing <Task(PythonOperator): get_input_data> on 2023-02-19 14:31:47.482838+00:00
[2023-02-19 14:31:49,606] {standard_task_runner.py:52} INFO - Started process 392 to run task
[2023-02-19 14:31:49,611] {standard_task_runner.py:79} INFO - Running: ['***', 'tasks', 'run', 'autoetl-coordinates', 'get_input_data', 'manual__2023-02-19T14:31:47.482838+00:00', '--job-id', '4', '--raw', '--subdir', 'DAGS_FOLDER/autoetl-coordinates.py', '--cfg-path', '/tmp/tmpw5rqucq7', '--error-file', '/tmp/tmp2v08ui0h']
[2023-02-19 14:31:49,614] {standard_task_runner.py:80} INFO - Job 4: Subtask get_input_data
[2023-02-19 14:31:49,683] {task_command.py:369} INFO - Running <TaskInstance: autoetl-coordinates.get_input_data manual__2023-02-19T14:31:47.482838+00:00 [running]> on host 28bff766bd86
[2023-02-19 14:31:49,764] {taskinstance.py:1571} INFO - Exporting the following env vars:
AIRFLOW_CTX_DAG_OWNER=***
AIRFLOW_CTX_DAG_ID=autoetl-coordinates
AIRFLOW_CTX_TASK_ID=get_input_data
AIRFLOW_CTX_EXECUTION_DATE=2023-02-19T14:31:47.482838+00:00
AIRFLOW_CTX_TRY_NUMBER=1
AIRFLOW_CTX_DAG_RUN_ID=manual__2023-02-19T14:31:47.482838+00:00
[2023-02-19 14:31:49,766] {logging_mixin.py:115} INFO - Get Locations URL and Load into Pandas Dataframe
[2023-02-19 14:31:53,594] {logging_mixin.py:115} WARNING - /home/***/.local/lib/python3.7/site-packages/***/operators/python.py:189 DtypeWarning: Columns (11,12,14,20) have mixed types.Specify dtype option on import or set low_memory=False.
[2023-02-19 14:32:04,649] {logging_mixin.py:115} INFO - Get buildings data
[2023-02-19 14:32:18,870] {logging_mixin.py:115} INFO - Get parcels data
[2023-02-19 14:32:19,498] {taskinstance.py:1889} ERROR - Task failed with exception
Traceback (most recent call last):
  File "/home/airflow/.local/lib/python3.7/site-packages/airflow/operators/python.py", line 171, in execute
    return_value = self.execute_callable()
  File "/home/airflow/.local/lib/python3.7/site-packages/airflow/operators/python.py", line 189, in execute_callable
    return self.python_callable(*self.op_args, **self.op_kwargs)
  File "/opt/airflow/dags/autoetl-coordinates.py", line 42, in get_input_data
    gdown.download(reconstructed_parcels_url, output, quiet=False)
  File "/home/airflow/.local/lib/python3.7/site-packages/gdown/download.py", line 215, in download
    for file in os.listdir(osp.dirname(output) or "."):
FileNotFoundError: [Errno 2] No such file or directory: '/data'
[2023-02-19 14:32:19,576] {taskinstance.py:1400} INFO - Marking task as FAILED. dag_id=autoetl-coordinates, task_id=get_input_data, execution_date=20230219T143147, start_date=20230219T143149, end_date=20230219T143219
[2023-02-19 14:32:20,279] {standard_task_runner.py:97} ERROR - Failed to execute job 4 for task get_input_data ([Errno 2] No such file or directory: '/data'; 392)
[2023-02-19 14:32:20,404] {local_task_job.py:221} WARNING - State of this instance has been externally set to failed. Terminating instance.
[2023-02-19 14:32:20,499] {process_utils.py:129} INFO - Sending Signals.SIGTERM to group 392. PIDs of all processes in the group: [392]
[2023-02-19 14:32:20,503] {process_utils.py:80} INFO - Sending the signal Signals.SIGTERM to group 392
[2023-02-19 14:32:20,664] {process_utils.py:75} INFO - Process psutil.Process(pid=392, status='terminated', exitcode=1, started='14:31:48') (392) terminated with exit code 1
