[2023-02-19 20:53:59,895] {taskinstance.py:1159} INFO - Dependencies all met for <TaskInstance: autoetl-coordinates.get_new_geo manual__2023-02-19T20:52:54.993838+00:00 [queued]>
[2023-02-19 20:53:59,909] {taskinstance.py:1159} INFO - Dependencies all met for <TaskInstance: autoetl-coordinates.get_new_geo manual__2023-02-19T20:52:54.993838+00:00 [queued]>
[2023-02-19 20:53:59,910] {taskinstance.py:1356} INFO - 
--------------------------------------------------------------------------------
[2023-02-19 20:53:59,911] {taskinstance.py:1357} INFO - Starting attempt 1 of 1
[2023-02-19 20:53:59,912] {taskinstance.py:1358} INFO - 
--------------------------------------------------------------------------------
[2023-02-19 20:53:59,926] {taskinstance.py:1377} INFO - Executing <Task(PythonOperator): get_new_geo> on 2023-02-19 20:52:54.993838+00:00
[2023-02-19 20:53:59,935] {standard_task_runner.py:52} INFO - Started process 267 to run task
[2023-02-19 20:53:59,941] {standard_task_runner.py:79} INFO - Running: ['***', 'tasks', 'run', 'autoetl-coordinates', 'get_new_geo', 'manual__2023-02-19T20:52:54.993838+00:00', '--job-id', '3', '--raw', '--subdir', 'DAGS_FOLDER/autoetl-coordinates.py', '--cfg-path', '/tmp/tmprkmhc53b', '--error-file', '/tmp/tmpw5vlpp0r']
[2023-02-19 20:53:59,944] {standard_task_runner.py:80} INFO - Job 3: Subtask get_new_geo
[2023-02-19 20:54:00,015] {task_command.py:369} INFO - Running <TaskInstance: autoetl-coordinates.get_new_geo manual__2023-02-19T20:52:54.993838+00:00 [running]> on host 83ee186d463f
[2023-02-19 20:54:00,124] {taskinstance.py:1571} INFO - Exporting the following env vars:
AIRFLOW_CTX_DAG_OWNER=***
AIRFLOW_CTX_DAG_ID=autoetl-coordinates
AIRFLOW_CTX_TASK_ID=get_new_geo
AIRFLOW_CTX_EXECUTION_DATE=2023-02-19T20:52:54.993838+00:00
AIRFLOW_CTX_TRY_NUMBER=1
AIRFLOW_CTX_DAG_RUN_ID=manual__2023-02-19T20:52:54.993838+00:00
[2023-02-19 20:54:00,126] {logging_mixin.py:115} INFO - Load Data
[2023-02-19 20:54:01,746] {logging_mixin.py:115} WARNING - /home/***/.local/lib/python3.7/site-packages/***/operators/python.py:189 DtypeWarning: Columns (11,12,14,20) have mixed types.Specify dtype option on import or set low_memory=False.
[2023-02-19 21:05:04,507] {logging_mixin.py:115} INFO - Create Join Table
[2023-02-19 21:05:04,645] {logging_mixin.py:115} WARNING - /opt/***/dags/autoetl-coordinates.py:69 FutureWarning: The default value of regex will change from True to False in a future version.
[2023-02-19 21:05:04,794] {logging_mixin.py:115} WARNING - /opt/***/dags/autoetl-coordinates.py:69 SettingWithCopyWarning: 
A value is trying to be set on a copy of a slice from a DataFrame.
Try using .loc[row_indexer,col_indexer] = value instead

See the caveats in the documentation: https://pandas.pydata.org/pandas-docs/stable/user_guide/indexing.html#returning-a-view-versus-a-copy
[2023-02-19 21:05:09,736] {logging_mixin.py:115} INFO - Define Functions
[2023-02-19 21:05:09,740] {logging_mixin.py:115} INFO - Run distance function and get updated information
[2023-02-19 21:32:58,082] {logging_mixin.py:115} INFO - Clean updated locations
[2023-02-19 21:32:58,504] {taskinstance.py:1889} ERROR - Task failed with exception
Traceback (most recent call last):
  File "/home/airflow/.local/lib/python3.7/site-packages/pandas/core/indexes/range.py", line 385, in get_loc
    return self._range.index(new_key)
ValueError: 1 is not in range

The above exception was the direct cause of the following exception:

Traceback (most recent call last):
  File "/home/airflow/.local/lib/python3.7/site-packages/airflow/operators/python.py", line 171, in execute
    return_value = self.execute_callable()
  File "/home/airflow/.local/lib/python3.7/site-packages/airflow/operators/python.py", line 189, in execute_callable
    return self.python_callable(*self.op_args, **self.op_kwargs)
  File "/opt/airflow/dags/autoetl-coordinates.py", line 168, in get_new_geo
    locations['updated_lon'] = locations['updated_geo'].str.split(',', expand = True)[1]
  File "/home/airflow/.local/lib/python3.7/site-packages/pandas/core/frame.py", line 3458, in __getitem__
    indexer = self.columns.get_loc(key)
  File "/home/airflow/.local/lib/python3.7/site-packages/pandas/core/indexes/range.py", line 387, in get_loc
    raise KeyError(key) from err
KeyError: 1
[2023-02-19 21:32:58,674] {taskinstance.py:1400} INFO - Marking task as FAILED. dag_id=autoetl-coordinates, task_id=get_new_geo, execution_date=20230219T205254, start_date=20230219T205359, end_date=20230219T213258
[2023-02-19 21:32:58,792] {standard_task_runner.py:97} ERROR - Failed to execute job 3 for task get_new_geo (1; 267)
[2023-02-19 21:33:01,005] {local_task_job.py:221} WARNING - State of this instance has been externally set to failed. Terminating instance.
[2023-02-19 21:33:01,203] {process_utils.py:129} INFO - Sending Signals.SIGTERM to group 267. PIDs of all processes in the group: [267]
[2023-02-19 21:33:01,220] {process_utils.py:80} INFO - Sending the signal Signals.SIGTERM to group 267
[2023-02-19 21:33:08,651] {process_utils.py:75} INFO - Process psutil.Process(pid=267, status='terminated', exitcode=1, started='20:53:59') (267) terminated with exit code 1
