[2023-02-20 12:52:54,188] {taskinstance.py:1159} INFO - Dependencies all met for <TaskInstance: autoetl-coordinates.get_new_geo manual__2023-02-20T12:51:41.217725+00:00 [queued]>
[2023-02-20 12:52:54,208] {taskinstance.py:1159} INFO - Dependencies all met for <TaskInstance: autoetl-coordinates.get_new_geo manual__2023-02-20T12:51:41.217725+00:00 [queued]>
[2023-02-20 12:52:54,212] {taskinstance.py:1356} INFO - 
--------------------------------------------------------------------------------
[2023-02-20 12:52:54,213] {taskinstance.py:1357} INFO - Starting attempt 1 of 1
[2023-02-20 12:52:54,214] {taskinstance.py:1358} INFO - 
--------------------------------------------------------------------------------
[2023-02-20 12:52:54,241] {taskinstance.py:1377} INFO - Executing <Task(PythonOperator): get_new_geo> on 2023-02-20 12:51:41.217725+00:00
[2023-02-20 12:52:54,251] {standard_task_runner.py:52} INFO - Started process 253 to run task
[2023-02-20 12:52:54,261] {standard_task_runner.py:79} INFO - Running: ['***', 'tasks', 'run', 'autoetl-coordinates', 'get_new_geo', 'manual__2023-02-20T12:51:41.217725+00:00', '--job-id', '4', '--raw', '--subdir', 'DAGS_FOLDER/autoetl-coordinates.py', '--cfg-path', '/tmp/tmpheo5tbx3', '--error-file', '/tmp/tmpqejulo5q']
[2023-02-20 12:52:54,264] {standard_task_runner.py:80} INFO - Job 4: Subtask get_new_geo
[2023-02-20 12:52:54,360] {task_command.py:369} INFO - Running <TaskInstance: autoetl-coordinates.get_new_geo manual__2023-02-20T12:51:41.217725+00:00 [running]> on host 08ba3386fdbc
[2023-02-20 12:52:54,474] {taskinstance.py:1571} INFO - Exporting the following env vars:
AIRFLOW_CTX_DAG_OWNER=***
AIRFLOW_CTX_DAG_ID=autoetl-coordinates
AIRFLOW_CTX_TASK_ID=get_new_geo
AIRFLOW_CTX_EXECUTION_DATE=2023-02-20T12:51:41.217725+00:00
AIRFLOW_CTX_TRY_NUMBER=1
AIRFLOW_CTX_DAG_RUN_ID=manual__2023-02-20T12:51:41.217725+00:00
[2023-02-20 12:52:54,477] {logging_mixin.py:115} INFO - Load Data
[2023-02-20 12:52:55,765] {logging_mixin.py:115} WARNING - /home/***/.local/lib/python3.7/site-packages/***/operators/python.py:189 DtypeWarning: Columns (11,12,14,20) have mixed types.Specify dtype option on import or set low_memory=False.
[2023-02-20 12:55:22,436] {local_task_job.py:221} WARNING - State of this instance has been externally set to failed. Terminating instance.
[2023-02-20 12:55:22,557] {process_utils.py:129} INFO - Sending Signals.SIGTERM to group 253. PIDs of all processes in the group: [253]
[2023-02-20 12:55:22,562] {process_utils.py:80} INFO - Sending the signal Signals.SIGTERM to group 253
[2023-02-20 12:55:22,575] {taskinstance.py:1541} ERROR - Received SIGTERM. Terminating subprocesses.
[2023-02-20 12:55:25,402] {process_utils.py:75} INFO - Process psutil.Process(pid=253, status='terminated', exitcode=0, started='12:52:53') (253) terminated with exit code 0
