[2023-02-19 21:44:07,000] {taskinstance.py:1159} INFO - Dependencies all met for <TaskInstance: autoetl-coordinates.get_new_geo manual__2023-02-19T21:43:08.785057+00:00 [queued]>
[2023-02-19 21:44:07,012] {taskinstance.py:1159} INFO - Dependencies all met for <TaskInstance: autoetl-coordinates.get_new_geo manual__2023-02-19T21:43:08.785057+00:00 [queued]>
[2023-02-19 21:44:07,014] {taskinstance.py:1356} INFO - 
--------------------------------------------------------------------------------
[2023-02-19 21:44:07,016] {taskinstance.py:1357} INFO - Starting attempt 1 of 1
[2023-02-19 21:44:07,017] {taskinstance.py:1358} INFO - 
--------------------------------------------------------------------------------
[2023-02-19 21:44:07,032] {taskinstance.py:1377} INFO - Executing <Task(PythonOperator): get_new_geo> on 2023-02-19 21:43:08.785057+00:00
[2023-02-19 21:44:07,042] {standard_task_runner.py:52} INFO - Started process 859 to run task
[2023-02-19 21:44:07,047] {standard_task_runner.py:79} INFO - Running: ['***', 'tasks', 'run', 'autoetl-coordinates', 'get_new_geo', 'manual__2023-02-19T21:43:08.785057+00:00', '--job-id', '6', '--raw', '--subdir', 'DAGS_FOLDER/autoetl-coordinates.py', '--cfg-path', '/tmp/tmpcssbmf8j', '--error-file', '/tmp/tmp25qxpf1l']
[2023-02-19 21:44:07,048] {standard_task_runner.py:80} INFO - Job 6: Subtask get_new_geo
[2023-02-19 21:44:07,113] {task_command.py:369} INFO - Running <TaskInstance: autoetl-coordinates.get_new_geo manual__2023-02-19T21:43:08.785057+00:00 [running]> on host 83ee186d463f
[2023-02-19 21:44:07,194] {taskinstance.py:1571} INFO - Exporting the following env vars:
AIRFLOW_CTX_DAG_OWNER=***
AIRFLOW_CTX_DAG_ID=autoetl-coordinates
AIRFLOW_CTX_TASK_ID=get_new_geo
AIRFLOW_CTX_EXECUTION_DATE=2023-02-19T21:43:08.785057+00:00
AIRFLOW_CTX_TRY_NUMBER=1
AIRFLOW_CTX_DAG_RUN_ID=manual__2023-02-19T21:43:08.785057+00:00
[2023-02-19 21:44:07,197] {logging_mixin.py:115} INFO - Load Data
[2023-02-19 21:44:08,582] {logging_mixin.py:115} WARNING - /home/***/.local/lib/python3.7/site-packages/***/operators/python.py:189 DtypeWarning: Columns (11,12,14,20) have mixed types.Specify dtype option on import or set low_memory=False.
[2023-02-19 21:46:14,513] {local_task_job.py:221} WARNING - State of this instance has been externally set to failed. Terminating instance.
[2023-02-19 21:46:14,863] {process_utils.py:129} INFO - Sending Signals.SIGTERM to group 859. PIDs of all processes in the group: [859]
[2023-02-19 21:46:14,875] {process_utils.py:80} INFO - Sending the signal Signals.SIGTERM to group 859
[2023-02-19 21:46:14,950] {taskinstance.py:1541} ERROR - Received SIGTERM. Terminating subprocesses.
[2023-02-19 21:46:19,681] {process_utils.py:75} INFO - Process psutil.Process(pid=859, status='terminated', exitcode=0, started='21:44:06') (859) terminated with exit code 0
