[2023-02-20 00:47:35,334] {taskinstance.py:1159} INFO - Dependencies all met for <TaskInstance: autoetl-coordinates.get_new_geo manual__2023-02-20T00:46:37.009572+00:00 [queued]>
[2023-02-20 00:47:35,357] {taskinstance.py:1159} INFO - Dependencies all met for <TaskInstance: autoetl-coordinates.get_new_geo manual__2023-02-20T00:46:37.009572+00:00 [queued]>
[2023-02-20 00:47:35,359] {taskinstance.py:1356} INFO - 
--------------------------------------------------------------------------------
[2023-02-20 00:47:35,361] {taskinstance.py:1357} INFO - Starting attempt 1 of 1
[2023-02-20 00:47:35,363] {taskinstance.py:1358} INFO - 
--------------------------------------------------------------------------------
[2023-02-20 00:47:35,390] {taskinstance.py:1377} INFO - Executing <Task(PythonOperator): get_new_geo> on 2023-02-20 00:46:37.009572+00:00
[2023-02-20 00:47:35,409] {standard_task_runner.py:52} INFO - Started process 4752 to run task
[2023-02-20 00:47:35,418] {standard_task_runner.py:79} INFO - Running: ['***', 'tasks', 'run', 'autoetl-coordinates', 'get_new_geo', 'manual__2023-02-20T00:46:37.009572+00:00', '--job-id', '18', '--raw', '--subdir', 'DAGS_FOLDER/autoetl-coordinates.py', '--cfg-path', '/tmp/tmpzx2ckqi7', '--error-file', '/tmp/tmp_rxwajfr']
[2023-02-20 00:47:35,420] {standard_task_runner.py:80} INFO - Job 18: Subtask get_new_geo
[2023-02-20 00:47:35,510] {task_command.py:369} INFO - Running <TaskInstance: autoetl-coordinates.get_new_geo manual__2023-02-20T00:46:37.009572+00:00 [running]> on host 83ee186d463f
[2023-02-20 00:47:35,598] {taskinstance.py:1571} INFO - Exporting the following env vars:
AIRFLOW_CTX_DAG_OWNER=***
AIRFLOW_CTX_DAG_ID=autoetl-coordinates
AIRFLOW_CTX_TASK_ID=get_new_geo
AIRFLOW_CTX_EXECUTION_DATE=2023-02-20T00:46:37.009572+00:00
AIRFLOW_CTX_TRY_NUMBER=1
AIRFLOW_CTX_DAG_RUN_ID=manual__2023-02-20T00:46:37.009572+00:00
[2023-02-20 00:47:35,600] {logging_mixin.py:115} INFO - Load Data
[2023-02-20 00:47:36,874] {logging_mixin.py:115} WARNING - /home/***/.local/lib/python3.7/site-packages/***/operators/python.py:189 DtypeWarning: Columns (11,12,14,20) have mixed types.Specify dtype option on import or set low_memory=False.
[2023-02-20 00:59:15,344] {logging_mixin.py:115} INFO - Create Join Table
[2023-02-20 00:59:15,602] {logging_mixin.py:115} WARNING - /opt/***/dags/autoetl-coordinates.py:69 FutureWarning: The default value of regex will change from True to False in a future version.
[2023-02-20 00:59:15,744] {logging_mixin.py:115} WARNING - /opt/***/dags/autoetl-coordinates.py:69 SettingWithCopyWarning: 
A value is trying to be set on a copy of a slice from a DataFrame.
Try using .loc[row_indexer,col_indexer] = value instead

See the caveats in the documentation: https://pandas.pydata.org/pandas-docs/stable/user_guide/indexing.html#returning-a-view-versus-a-copy
[2023-02-20 00:59:20,326] {logging_mixin.py:115} INFO - Define Functions
[2023-02-20 00:59:20,335] {logging_mixin.py:115} INFO - TEMP CREATE SAMPLE
[2023-02-20 00:59:21,710] {logging_mixin.py:115} INFO - Run distance function and get updated information
[2023-02-20 00:59:31,989] {logging_mixin.py:115} INFO - TEMP SAVE FOR TESTING, TO REMOVE
[2023-02-20 00:59:32,333] {logging_mixin.py:115} INFO - Clean updated locations
[2023-02-20 00:59:32,347] {taskinstance.py:1889} ERROR - Task failed with exception
Traceback (most recent call last):
  File "/home/airflow/.local/lib/python3.7/site-packages/airflow/operators/python.py", line 171, in execute
    return_value = self.execute_callable()
  File "/home/airflow/.local/lib/python3.7/site-packages/airflow/operators/python.py", line 189, in execute_callable
    return self.python_callable(*self.op_args, **self.op_kwargs)
  File "/opt/airflow/dags/autoetl-coordinates.py", line 177, in get_new_geo
    locations['updated_lon'] = split_df[[1]]
  File "/home/airflow/.local/lib/python3.7/site-packages/pandas/core/frame.py", line 3464, in __getitem__
    indexer = self.loc._get_listlike_indexer(key, axis=1)[1]
  File "/home/airflow/.local/lib/python3.7/site-packages/pandas/core/indexing.py", line 1314, in _get_listlike_indexer
    self._validate_read_indexer(keyarr, indexer, axis)
  File "/home/airflow/.local/lib/python3.7/site-packages/pandas/core/indexing.py", line 1374, in _validate_read_indexer
    raise KeyError(f"None of [{key}] are in the [{axis_name}]")
KeyError: "None of [Int64Index([1], dtype='int64')] are in the [columns]"
[2023-02-20 00:59:32,461] {taskinstance.py:1400} INFO - Marking task as FAILED. dag_id=autoetl-coordinates, task_id=get_new_geo, execution_date=20230220T004637, start_date=20230220T004735, end_date=20230220T005932
[2023-02-20 00:59:32,572] {standard_task_runner.py:97} ERROR - Failed to execute job 18 for task get_new_geo ("None of [Int64Index([1], dtype='int64')] are in the [columns]"; 4752)
[2023-02-20 00:59:35,411] {local_task_job.py:156} INFO - Task exited with return code 1
[2023-02-20 00:59:35,600] {local_task_job.py:273} INFO - 0 downstream tasks scheduled from follow-on schedule check
