[2023-02-20 01:17:59,320] {taskinstance.py:1159} INFO - Dependencies all met for <TaskInstance: autoetl-coordinates.get_mapping manual__2023-02-20T01:17:48.166156+00:00 [queued]>
[2023-02-20 01:17:59,335] {taskinstance.py:1159} INFO - Dependencies all met for <TaskInstance: autoetl-coordinates.get_mapping manual__2023-02-20T01:17:48.166156+00:00 [queued]>
[2023-02-20 01:17:59,337] {taskinstance.py:1356} INFO - 
--------------------------------------------------------------------------------
[2023-02-20 01:17:59,339] {taskinstance.py:1357} INFO - Starting attempt 1 of 1
[2023-02-20 01:17:59,340] {taskinstance.py:1358} INFO - 
--------------------------------------------------------------------------------
[2023-02-20 01:17:59,359] {taskinstance.py:1377} INFO - Executing <Task(PythonOperator): get_mapping> on 2023-02-20 01:17:48.166156+00:00
[2023-02-20 01:17:59,368] {standard_task_runner.py:52} INFO - Started process 5546 to run task
[2023-02-20 01:17:59,377] {standard_task_runner.py:79} INFO - Running: ['***', 'tasks', 'run', 'autoetl-coordinates', 'get_mapping', 'manual__2023-02-20T01:17:48.166156+00:00', '--job-id', '27', '--raw', '--subdir', 'DAGS_FOLDER/autoetl-coordinates.py', '--cfg-path', '/tmp/tmp1uuk75cq', '--error-file', '/tmp/tmp5l6mc5go']
[2023-02-20 01:17:59,381] {standard_task_runner.py:80} INFO - Job 27: Subtask get_mapping
[2023-02-20 01:17:59,475] {task_command.py:369} INFO - Running <TaskInstance: autoetl-coordinates.get_mapping manual__2023-02-20T01:17:48.166156+00:00 [running]> on host 83ee186d463f
[2023-02-20 01:17:59,592] {taskinstance.py:1571} INFO - Exporting the following env vars:
AIRFLOW_CTX_DAG_OWNER=***
AIRFLOW_CTX_DAG_ID=autoetl-coordinates
AIRFLOW_CTX_TASK_ID=get_mapping
AIRFLOW_CTX_EXECUTION_DATE=2023-02-20T01:17:48.166156+00:00
AIRFLOW_CTX_TRY_NUMBER=1
AIRFLOW_CTX_DAG_RUN_ID=manual__2023-02-20T01:17:48.166156+00:00
[2023-02-20 01:17:59,598] {logging_mixin.py:115} INFO - Load Data
[2023-02-20 01:18:00,767] {logging_mixin.py:115} WARNING - /home/***/.local/lib/python3.7/site-packages/***/operators/python.py:189 DtypeWarning: Columns (12,13,15,21) have mixed types.Specify dtype option on import or set low_memory=False.
[2023-02-20 01:18:52,570] {logging_mixin.py:115} INFO - Load mapping config
[2023-02-20 01:18:52,575] {taskinstance.py:1889} ERROR - Task failed with exception
Traceback (most recent call last):
  File "/home/airflow/.local/lib/python3.7/site-packages/airflow/operators/python.py", line 171, in execute
    return_value = self.execute_callable()
  File "/home/airflow/.local/lib/python3.7/site-packages/airflow/operators/python.py", line 189, in execute_callable
    return self.python_callable(*self.op_args, **self.op_kwargs)
  File "/opt/airflow/dags/autoetl-coordinates.py", line 217, in get_mapping
    with open('./keplergl_config.pkl', 'rb') as f:
FileNotFoundError: [Errno 2] No such file or directory: './keplergl_config.pkl'
[2023-02-20 01:18:52,602] {taskinstance.py:1400} INFO - Marking task as FAILED. dag_id=autoetl-coordinates, task_id=get_mapping, execution_date=20230220T011748, start_date=20230220T011759, end_date=20230220T011852
[2023-02-20 01:18:52,622] {standard_task_runner.py:97} ERROR - Failed to execute job 27 for task get_mapping ([Errno 2] No such file or directory: './keplergl_config.pkl'; 5546)
[2023-02-20 01:18:52,792] {local_task_job.py:156} INFO - Task exited with return code 1
[2023-02-20 01:18:52,837] {local_task_job.py:273} INFO - 0 downstream tasks scheduled from follow-on schedule check
