[2023-02-19 14:50:00,981] {taskinstance.py:1159} INFO - Dependencies all met for <TaskInstance: autoetl-coordinates.convert_geojson manual__2023-02-19T14:48:57.378576+00:00 [queued]>
[2023-02-19 14:50:00,995] {taskinstance.py:1159} INFO - Dependencies all met for <TaskInstance: autoetl-coordinates.convert_geojson manual__2023-02-19T14:48:57.378576+00:00 [queued]>
[2023-02-19 14:50:00,996] {taskinstance.py:1356} INFO - 
--------------------------------------------------------------------------------
[2023-02-19 14:50:00,997] {taskinstance.py:1357} INFO - Starting attempt 1 of 1
[2023-02-19 14:50:00,998] {taskinstance.py:1358} INFO - 
--------------------------------------------------------------------------------
[2023-02-19 14:50:01,016] {taskinstance.py:1377} INFO - Executing <Task(BashOperator): convert_geojson> on 2023-02-19 14:48:57.378576+00:00
[2023-02-19 14:50:01,025] {standard_task_runner.py:52} INFO - Started process 642 to run task
[2023-02-19 14:50:01,031] {standard_task_runner.py:79} INFO - Running: ['***', 'tasks', 'run', 'autoetl-coordinates', 'convert_geojson', 'manual__2023-02-19T14:48:57.378576+00:00', '--job-id', '7', '--raw', '--subdir', 'DAGS_FOLDER/autoetl-coordinates.py', '--cfg-path', '/tmp/tmpwgbb7_rb', '--error-file', '/tmp/tmpi1o9vr9n']
[2023-02-19 14:50:01,034] {standard_task_runner.py:80} INFO - Job 7: Subtask convert_geojson
[2023-02-19 14:50:01,111] {task_command.py:369} INFO - Running <TaskInstance: autoetl-coordinates.convert_geojson manual__2023-02-19T14:48:57.378576+00:00 [running]> on host 28bff766bd86
[2023-02-19 14:50:01,160] {taskinstance.py:1889} ERROR - Task failed with exception
Traceback (most recent call last):
  File "/home/airflow/.local/lib/python3.7/site-packages/airflow/models/taskinstance.py", line 1451, in _run_raw_task
    self._execute_task_with_callbacks(context, test_mode)
  File "/home/airflow/.local/lib/python3.7/site-packages/airflow/models/taskinstance.py", line 1555, in _execute_task_with_callbacks
    task_orig = self.render_templates(context=context)
  File "/home/airflow/.local/lib/python3.7/site-packages/airflow/models/taskinstance.py", line 2202, in render_templates
    rendered_task = self.task.render_template_fields(context)
  File "/home/airflow/.local/lib/python3.7/site-packages/airflow/models/baseoperator.py", line 1179, in render_template_fields
    self._do_render_template_fields(self, self.template_fields, context, jinja_env, set())
  File "/home/airflow/.local/lib/python3.7/site-packages/airflow/utils/session.py", line 71, in wrapper
    return func(*args, session=session, **kwargs)
  File "/home/airflow/.local/lib/python3.7/site-packages/airflow/models/abstractoperator.py", line 348, in _do_render_template_fields
    seen_oids,
  File "/home/airflow/.local/lib/python3.7/site-packages/airflow/models/abstractoperator.py", line 385, in render_template
    template = jinja_env.get_template(value)
  File "/home/airflow/.local/lib/python3.7/site-packages/jinja2/environment.py", line 997, in get_template
    return self._load_template(name, globals)
  File "/home/airflow/.local/lib/python3.7/site-packages/jinja2/environment.py", line 958, in _load_template
    template = self.loader.load(self, name, self.make_globals(globals))
  File "/home/airflow/.local/lib/python3.7/site-packages/jinja2/loaders.py", line 125, in load
    source, filename, uptodate = self.get_source(environment, name)
  File "/home/airflow/.local/lib/python3.7/site-packages/jinja2/loaders.py", line 214, in get_source
    raise TemplateNotFound(template)
jinja2.exceptions.TemplateNotFound: ./data/convert_json.sh
[2023-02-19 14:50:01,189] {taskinstance.py:1400} INFO - Marking task as FAILED. dag_id=autoetl-coordinates, task_id=convert_geojson, execution_date=20230219T144857, start_date=20230219T145000, end_date=20230219T145001
[2023-02-19 14:50:01,205] {standard_task_runner.py:97} ERROR - Failed to execute job 7 for task convert_geojson (./data/convert_json.sh; 642)
[2023-02-19 14:50:01,245] {local_task_job.py:156} INFO - Task exited with return code 1
[2023-02-19 14:50:01,291] {local_task_job.py:273} INFO - 0 downstream tasks scheduled from follow-on schedule check
