[2023-02-20 01:34:20,730] {taskinstance.py:1159} INFO - Dependencies all met for <TaskInstance: autoetl-coordinates.get_new_geo manual__2023-02-20T01:33:39.314319+00:00 [queued]>
[2023-02-20 01:34:20,745] {taskinstance.py:1159} INFO - Dependencies all met for <TaskInstance: autoetl-coordinates.get_new_geo manual__2023-02-20T01:33:39.314319+00:00 [queued]>
[2023-02-20 01:34:20,746] {taskinstance.py:1356} INFO - 
--------------------------------------------------------------------------------
[2023-02-20 01:34:20,747] {taskinstance.py:1357} INFO - Starting attempt 1 of 1
[2023-02-20 01:34:20,749] {taskinstance.py:1358} INFO - 
--------------------------------------------------------------------------------
[2023-02-20 01:34:20,764] {taskinstance.py:1377} INFO - Executing <Task(PythonOperator): get_new_geo> on 2023-02-20 01:33:39.314319+00:00
[2023-02-20 01:34:20,774] {standard_task_runner.py:52} INFO - Started process 6001 to run task
[2023-02-20 01:34:20,778] {standard_task_runner.py:79} INFO - Running: ['***', 'tasks', 'run', 'autoetl-coordinates', 'get_new_geo', 'manual__2023-02-20T01:33:39.314319+00:00', '--job-id', '33', '--raw', '--subdir', 'DAGS_FOLDER/autoetl-coordinates.py', '--cfg-path', '/tmp/tmpfv0eq0qx', '--error-file', '/tmp/tmpksmgq6o3']
[2023-02-20 01:34:20,780] {standard_task_runner.py:80} INFO - Job 33: Subtask get_new_geo
[2023-02-20 01:34:20,846] {task_command.py:369} INFO - Running <TaskInstance: autoetl-coordinates.get_new_geo manual__2023-02-20T01:33:39.314319+00:00 [running]> on host 83ee186d463f
[2023-02-20 01:34:20,924] {taskinstance.py:1571} INFO - Exporting the following env vars:
AIRFLOW_CTX_DAG_OWNER=***
AIRFLOW_CTX_DAG_ID=autoetl-coordinates
AIRFLOW_CTX_TASK_ID=get_new_geo
AIRFLOW_CTX_EXECUTION_DATE=2023-02-20T01:33:39.314319+00:00
AIRFLOW_CTX_TRY_NUMBER=1
AIRFLOW_CTX_DAG_RUN_ID=manual__2023-02-20T01:33:39.314319+00:00
[2023-02-20 01:34:20,927] {logging_mixin.py:115} INFO - Load Data
[2023-02-20 01:34:21,932] {logging_mixin.py:115} WARNING - /home/***/.local/lib/python3.7/site-packages/***/operators/python.py:189 DtypeWarning: Columns (11,12,14,20) have mixed types.Specify dtype option on import or set low_memory=False.
[2023-02-20 01:44:48,515] {logging_mixin.py:115} INFO - Create Join Table
[2023-02-20 01:44:48,644] {logging_mixin.py:115} WARNING - /opt/***/dags/autoetl-coordinates.py:69 FutureWarning: The default value of regex will change from True to False in a future version.
[2023-02-20 01:44:48,789] {logging_mixin.py:115} WARNING - /opt/***/dags/autoetl-coordinates.py:69 SettingWithCopyWarning: 
A value is trying to be set on a copy of a slice from a DataFrame.
Try using .loc[row_indexer,col_indexer] = value instead

See the caveats in the documentation: https://pandas.pydata.org/pandas-docs/stable/user_guide/indexing.html#returning-a-view-versus-a-copy
[2023-02-20 01:44:51,485] {logging_mixin.py:115} INFO - Define Functions
[2023-02-20 01:44:51,487] {logging_mixin.py:115} INFO - Run distance function and get updated information
[2023-02-20 02:13:59,050] {logging_mixin.py:115} INFO - Save updated location file to data
[2023-02-20 02:14:35,677] {python.py:173} INFO - Done. Returned value was: None
[2023-02-20 02:14:36,107] {taskinstance.py:1400} INFO - Marking task as SUCCESS. dag_id=autoetl-coordinates, task_id=get_new_geo, execution_date=20230220T013339, start_date=20230220T013420, end_date=20230220T021436
[2023-02-20 02:14:40,278] {local_task_job.py:221} WARNING - State of this instance has been externally set to success. Terminating instance.
[2023-02-20 02:14:40,853] {process_utils.py:129} INFO - Sending Signals.SIGTERM to group 6001. PIDs of all processes in the group: [6001]
[2023-02-20 02:14:40,882] {process_utils.py:80} INFO - Sending the signal Signals.SIGTERM to group 6001
[2023-02-20 02:14:42,794] {process_utils.py:75} INFO - Process psutil.Process(pid=6001, status='terminated', exitcode=0, started='01:34:20') (6001) terminated with exit code 0
