[2023-02-19 14:27:17,447] {taskinstance.py:1159} INFO - Dependencies all met for <TaskInstance: autoetl-coordinates.get_input_data manual__2023-02-19T14:27:15.343569+00:00 [queued]>
[2023-02-19 14:27:17,460] {taskinstance.py:1159} INFO - Dependencies all met for <TaskInstance: autoetl-coordinates.get_input_data manual__2023-02-19T14:27:15.343569+00:00 [queued]>
[2023-02-19 14:27:17,461] {taskinstance.py:1356} INFO - 
--------------------------------------------------------------------------------
[2023-02-19 14:27:17,462] {taskinstance.py:1357} INFO - Starting attempt 1 of 1
[2023-02-19 14:27:17,463] {taskinstance.py:1358} INFO - 
--------------------------------------------------------------------------------
[2023-02-19 14:27:17,478] {taskinstance.py:1377} INFO - Executing <Task(PythonOperator): get_input_data> on 2023-02-19 14:27:15.343569+00:00
[2023-02-19 14:27:17,487] {standard_task_runner.py:52} INFO - Started process 323 to run task
[2023-02-19 14:27:17,492] {standard_task_runner.py:79} INFO - Running: ['***', 'tasks', 'run', 'autoetl-coordinates', 'get_input_data', 'manual__2023-02-19T14:27:15.343569+00:00', '--job-id', '3', '--raw', '--subdir', 'DAGS_FOLDER/autoetl-coordinates.py', '--cfg-path', '/tmp/tmpax2fw94j', '--error-file', '/tmp/tmp1hf0hcxf']
[2023-02-19 14:27:17,494] {standard_task_runner.py:80} INFO - Job 3: Subtask get_input_data
[2023-02-19 14:27:17,563] {task_command.py:369} INFO - Running <TaskInstance: autoetl-coordinates.get_input_data manual__2023-02-19T14:27:15.343569+00:00 [running]> on host 28bff766bd86
[2023-02-19 14:27:17,642] {taskinstance.py:1571} INFO - Exporting the following env vars:
AIRFLOW_CTX_DAG_OWNER=***
AIRFLOW_CTX_DAG_ID=autoetl-coordinates
AIRFLOW_CTX_TASK_ID=get_input_data
AIRFLOW_CTX_EXECUTION_DATE=2023-02-19T14:27:15.343569+00:00
AIRFLOW_CTX_TRY_NUMBER=1
AIRFLOW_CTX_DAG_RUN_ID=manual__2023-02-19T14:27:15.343569+00:00
[2023-02-19 14:27:21,043] {logging_mixin.py:115} WARNING - /home/***/.local/lib/python3.7/site-packages/***/operators/python.py:189 DtypeWarning: Columns (11,12,14,20) have mixed types.Specify dtype option on import or set low_memory=False.
[2023-02-19 14:27:43,149] {taskinstance.py:1889} ERROR - Task failed with exception
Traceback (most recent call last):
  File "/home/airflow/.local/lib/python3.7/site-packages/airflow/operators/python.py", line 171, in execute
    return_value = self.execute_callable()
  File "/home/airflow/.local/lib/python3.7/site-packages/airflow/operators/python.py", line 189, in execute_callable
    return self.python_callable(*self.op_args, **self.op_kwargs)
  File "/opt/airflow/dags/autoetl-coordinates.py", line 42, in get_input_data
    gdown.download(reconstructed_parcels_url, output, quiet=False)
  File "/home/airflow/.local/lib/python3.7/site-packages/gdown/download.py", line 215, in download
    for file in os.listdir(osp.dirname(output) or "."):
FileNotFoundError: [Errno 2] No such file or directory: '/data'
[2023-02-19 14:27:43,166] {taskinstance.py:1400} INFO - Marking task as FAILED. dag_id=autoetl-coordinates, task_id=get_input_data, execution_date=20230219T142715, start_date=20230219T142717, end_date=20230219T142743
[2023-02-19 14:27:43,179] {standard_task_runner.py:97} ERROR - Failed to execute job 3 for task get_input_data ([Errno 2] No such file or directory: '/data'; 323)
[2023-02-19 14:27:43,213] {local_task_job.py:156} INFO - Task exited with return code 1
[2023-02-19 14:27:43,252] {local_task_job.py:273} INFO - 0 downstream tasks scheduled from follow-on schedule check
